Traceback (most recent call last):
  File "/usr/local/lib/python3.12/dist-packages/scipy/io/matlab/_mio.py", line 39, in _open_file
    return open(file_like, mode), True
           ^^^^^^^^^^^^^^^^^^^^^
FileNotFoundError: [Errno 2] No such file or directory: '/sandbox/datasets/mask/changjiang_mask.mat'

During handling of the above exception, another exception occurred:

Traceback (most recent call last):
  File "/sandbox/code/feature_engineering_changjiang_20250610_221829_110803_feature_engineering_changjiang.py", line 24, in <module>
    mask_data = scipy.io.loadmat(os.path.join(MASK_DIR, 'changjiang_mask.mat'))
                ^^^^^^^^^^^^^^^^^^^^^^^^^^^^^^^^^^^^^^^^^^^^^^^^^^^^^^^^^^^^^^^
  File "/usr/local/lib/python3.12/dist-packages/scipy/io/matlab/_mio.py", line 233, in loadmat
    with _open_file_context(file_name, appendmat) as f:
         ^^^^^^^^^^^^^^^^^^^^^^^^^^^^^^^^^^^^^^^^
  File "/usr/lib/python3.12/contextlib.py", line 137, in __enter__
    return next(self.gen)
           ^^^^^^^^^^^^^^
  File "/usr/local/lib/python3.12/dist-packages/scipy/io/matlab/_mio.py", line 17, in _open_file_context
    f, opened = _open_file(file_like, appendmat, mode)
                ^^^^^^^^^^^^^^^^^^^^^^^^^^^^^^^^^^^^^^
  File "/usr/local/lib/python3.12/dist-packages/scipy/io/matlab/_mio.py", line 45, in _open_file
    return open(file_like, mode), True
           ^^^^^^^^^^^^^^^^^^^^^
FileNotFoundError: [Errno 2] No such file or directory: '/sandbox/datasets/mask/changjiang_mask.mat'
